<mujoco model="A1_Robot">
    <compiler angle="radian" meshdir="/home/kavehakbarihamed/raisim/workspace/A1_DeePC/rsc/meshes" 
        texturedir="/home/kavehakbarihamed/raisim/workspace/A1_DeePC/rsc"/>
    <size njmax="500" nconmax="100" />
    <option gravity="0 0 -9.806" solver="Newton" tolerance="1e-12" impratio="100" timestep="0.001">
        <flag sensornoise="disable"/>
    </option>

    <default>
        <geom contype="1" conaffinity="1" friction="0.9 0.3 0.3" rgba="0.5 0.6 0.7 1" margin="0.001" group="0"/>

        <light castshadow="true" diffuse="0.9 0.9 0.9" ambient="0.1 0.1 0.1"/>
        <motor ctrlrange="-33.5 33.5" ctrllimited="true"/>
        <camera fovy="60"/>
        <joint damping="0.01" armature="0.01" frictionloss="0.2" />
    
    </default>
    <default class="QuadColor">
        <geom rgba="0.12 0.12 0.12 1"/>
        <!-- <geom rgba="0.4 0.2 0.8 1"/> -->
    </default>

    <asset>
        <mesh name="trunk"        file="trunk.STL"       />
        <mesh name="hip"          file="hip.STL"         />
        <mesh name="thigh_mirror" file="thigh_right.STL" />
        <mesh name="calf"         file="calf.STL"        />
        <mesh name="thigh"        file="thigh_left.STL"  />
        <mesh name="scaled_trunk" file="trunk.STL"       scale ="1.15 1.15 1.15"/>
    </asset>

    <asset>
        <!-- <texture type="skybox" builtin="gradient" rgb1="0.6 0.6 0.6" rgb2="0.6 0.6 0.6" 
            width="512" height="512"/> -->
        <texture type="skybox" builtin="none" file="desert.png" 
            gridsize="3 4" gridlayout = ".U..LFRB.D.." />
        <texture name="texplane" type="2d" builtin="checker" rgb1="0.55 0.55 0.55" rgb2="0.42 0.42 0.42" 
            width="512" height="512"/>
        <material name="matplane" texture="texplane" texrepeat="1 1" texuniform="true"
            reflectance="0.01" shininess="0.5" specular="0.0" emission="0"/>
    </asset>

    <visual>
        <rgba haze="0.45 0.45 0.45 1" com="0.502 1.0 0 0.5" contactforce="0 0.0 1 0.8" contactpoint="1.0 0 0 1"/>
        <scale com="0.2" forcewidth="0.05" contactwidth="0.20" contactheight="0.02"/>
        <quality shadowsize="2048"/>
        <map stiffness="700" shadowscale="0.25" fogstart="10" fogend="15" zfar="40" haze="1" force="0.005"/>
    </visual>

    <worldbody>
        <light directional="true" pos=" 0   0  10" dir="  0   0 -10" 
            castshadow="false"/>
        <light directional="true" pos=" 0 -10   2" dir="  0  10  -2" 
            castshadow="false"/>
        <light directional="true" pos=" 0  10   2" dir="  0 -10  -2" 
            castshadow="false"/>
            

        <camera name="track" mode="targetbodycom" target="trunk" pos="0 -10 2" xyaxes="1 0 0 0 0.707 0.707"/>
        <geom name='floor' type='plane' conaffinity='1' condim='3' contype='1' 
            rgba="1 1 1 1" material='matplane' pos='0 0 0' quat="1 0 0 0" size="0 0 1"/>

        <body name="trunk" pos="0 0 0.3" childclass="QuadColor">
            <inertial pos="0.0127283 0.00218554 0.000514891" quat="0.00186575 0.711506 0.000389649 0.702677" mass="4.714" diaginertia="0.0648213 0.0565803 0.0169323" />
            <joint type="free" />
            <geom type="mesh" contype="0" conaffinity="0" group="1" mesh="trunk"/>
            <geom size="0.1335 0.066 0.057" type="box" rgba="0.913725 0.913725 0.847059 0" />
            <geom size="0.0005 0.0005 0.0005" type="box" contype="0" conaffinity="0" group="1" rgba="0.8 0 0 0" />
            <site name="imu" pos="0 0 0"/>

            <body name="FR_hip" pos="0.183 -0.047 0">
                <inertial pos="-0.003311 -0.000635 3.1e-05" quat="0.507528 0.506268 0.491507 0.494499" mass="0.696" diaginertia="0.000807752 0.00055293 0.000468983" />
                <joint name="FR_hip_joint" pos="0 0 0" axis="1 0 0" limited="true" range="-0.802851 0.802851" />
                <geom quat="0 1 0 0" type="mesh" contype="0" conaffinity="0" group="1" mesh="hip" />
                <geom size="0.04 0.04" pos="0 -0.055 0" quat="0.707107 0.707107 0 0" type="cylinder" rgba="0.913725 0.913725 0.847059 0" />
                <body name="FR_thigh" pos="0 -0.08505 0">
                    <inertial pos="-0.003237 0.022327 -0.027326" quat="0.999125 -0.00256393 -0.0409531 -0.00806091" mass="1.013" diaginertia="0.00555739 0.00513936 0.00133944" />
                    <joint name="FR_thigh_joint" pos="0 0 0" axis="0 1 0" limited="true" range="-1.0472 4.18879" />
                    <geom type="mesh" contype="0" conaffinity="0" group="1" mesh="thigh_mirror" />
                    <geom size="0.1 0.01225 0.017" pos="0 0 -0.1" quat="0.707107 0 0.707107 0" type="box" rgba="0.913725 0.913725 0.847059 0" />
                    <body name="FR_calf" pos="0 0 -0.2">
                        <inertial pos="0.00472659 0 -0.131975" quat="0.706886 0.017653 0.017653 0.706886" mass="0.226" diaginertia="0.00340344 0.00339393 3.54834e-05" />
                        <joint name="FR_calf_joint" pos="0 0 0" axis="0 1 0" limited="true" range="-2.69653 -0.916298" />
                        <geom type="mesh" contype="0" conaffinity="0" group="1" mesh="calf" />
                        <geom size="0.1 0.008 0.008" pos="0 0 -0.1" quat="0.707107 0 0.707107 0" type="box" rgba="0 0 0 0" />
                        <geom name="FR_foot" size="0.02" pos="0 0 -0.2" rgba="0 0 0 0" />
                    </body>
                </body>
            </body>
            <body name="FL_hip" pos="0.183 0.047 0" childclass="QuadColor">
                <inertial pos="-0.003311 0.000635 3.1e-05" quat="0.494499 0.491507 0.506268 0.507528" mass="0.696" diaginertia="0.000807752 0.00055293 0.000468983" />
                <joint name="FL_hip_joint" pos="0 0 0" axis="1 0 0" limited="true" range="-0.802851 0.802851" />
                <geom type="mesh" contype="0" conaffinity="0" group="1" mesh="hip" />
                <geom size="0.04 0.04" pos="0 0.055 0" quat="0.707107 0.707107 0 0" type="cylinder" rgba="0.913725 0.913725 0.847059 0" />
                <body name="FL_thigh" pos="0 0.08505 0">
                    <inertial pos="-0.003237 -0.022327 -0.027326" quat="0.999125 0.00256393 -0.0409531 0.00806091" mass="1.013" diaginertia="0.00555739 0.00513936 0.00133944" />
                    <joint name="FL_thigh_joint" pos="0 0 0" axis="0 1 0" limited="true" range="-1.0472 4.18879" />
                    <geom type="mesh" contype="0" conaffinity="0" group="1" mesh="thigh" />
                    <geom size="0.1 0.01225 0.017" pos="0 0 -0.1" quat="0.707107 0 0.707107 0" type="box" rgba="0.913725 0.913725 0.847059 0" />
                    <body name="FL_calf" pos="0 0 -0.2">
                        <inertial pos="0.00472659 0 -0.131975" quat="0.706886 0.017653 0.017653 0.706886" mass="0.226" diaginertia="0.00340344 0.00339393 3.54834e-05" />
                        <joint name="FL_calf_joint" pos="0 0 0" axis="0 1 0" limited="true" range="-2.69653 -0.916298" />
                        <geom type="mesh" contype="0" conaffinity="0" group="1" mesh="calf" />
                        <geom size="0.1 0.008 0.008" pos="0 0 -0.1" quat="0.707107 0 0.707107 0" type="box" rgba="0 0 0 0" />
                        <geom name="FL_foot" size="0.02" pos="0 0 -0.2" rgba="0 0 0 0" />
                    </body>
                </body>
            </body>
            <body name="RR_hip" pos="-0.183 -0.047 0" childclass="QuadColor">
                <inertial pos="0.003311 -0.000635 3.1e-05" quat="0.491507 0.494499 0.507528 0.506268" mass="0.696" diaginertia="0.000807752 0.00055293 0.000468983" />
                <joint name="RR_hip_joint" pos="0 0 0" axis="1 0 0" limited="true" range="-0.802851 0.802851" />
                <geom quat="0 0 0 -1" type="mesh" contype="0" conaffinity="0" group="1" mesh="hip" />
                <geom size="0.04 0.04" pos="0 -0.055 0" quat="0.707107 0.707107 0 0" type="cylinder" rgba="0.913725 0.913725 0.847059 0" />
                <body name="RR_thigh" pos="0 -0.08505 0">
                    <inertial pos="-0.003237 0.022327 -0.027326" quat="0.999125 -0.00256393 -0.0409531 -0.00806091" mass="1.013" diaginertia="0.00555739 0.00513936 0.00133944" />
                    <joint name="RR_thigh_joint" pos="0 0 0" axis="0 1 0" limited="true" range="-1.0472 4.18879" />
                    <geom type="mesh" contype="0" conaffinity="0" group="1" mesh="thigh_mirror" />
                    <geom size="0.1 0.01225 0.017" pos="0 0 -0.1" quat="0.707107 0 0.707107 0" type="box" rgba="0.913725 0.913725 0.847059 0" />
                    <body name="RR_calf" pos="0 0 -0.2">
                        <inertial pos="0.00472659 0 -0.131975" quat="0.706886 0.017653 0.017653 0.706886" mass="0.226" diaginertia="0.00340344 0.00339393 3.54834e-05" />
                        <joint name="RR_calf_joint" pos="0 0 0" axis="0 1 0" limited="true" range="-2.69653 -0.916298" />
                        <geom type="mesh" contype="0" conaffinity="0" group="1" mesh="calf" />
                        <geom size="0.1 0.008 0.008" pos="0 0 -0.1" quat="0.707107 0 0.707107 0" type="box" rgba="0 0 0 0" />
                        <geom name="RR_foot" size="0.02" pos="0 0 -0.2" rgba="0 0 0 0" />
                    </body>
                </body>
            </body>
            <body name="RL_hip" pos="-0.183 0.047 0" childclass="QuadColor">
                <inertial pos="0.003311 0.000635 3.1e-05" quat="0.506268 0.507528 0.494499 0.491507" mass="0.696" diaginertia="0.000807752 0.00055293 0.000468983" />
                <joint name="RL_hip_joint" pos="0 0 0" axis="1 0 0" limited="true" range="-0.802851 0.802851" />
                <geom quat="0 0 1 0" type="mesh" contype="0" conaffinity="0" group="1" mesh="hip" />
                <geom size="0.04 0.04" pos="0 0.055 0" quat="0.707107 0.707107 0 0" type="cylinder" rgba="0.913725 0.913725 0.847059 0" />
                <body name="RL_thigh" pos="0 0.08505 0">
                    <inertial pos="-0.003237 -0.022327 -0.027326" quat="0.999125 0.00256393 -0.0409531 0.00806091" mass="1.013" diaginertia="0.00555739 0.00513936 0.00133944" />
                    <joint name="RL_thigh_joint" pos="0 0 0" axis="0 1 0" limited="true" range="-1.0472 4.18879" />
                    <geom type="mesh" contype="0" conaffinity="0" group="1" mesh="thigh" />
                    <geom size="0.1 0.01225 0.017" pos="0 0 -0.1" quat="0.707107 0 0.707107 0" type="box" rgba="0.913725 0.913725 0.847059 0" />
                    <body name="RL_calf" pos="0 0 -0.2">
                        <inertial pos="0.00472659 0 -0.131975" quat="0.706886 0.017653 0.017653 0.706886" mass="0.226" diaginertia="0.00340344 0.00339393 3.54834e-05" />
                        <joint name="RL_calf_joint" pos="0 0 0" axis="0 1 0" limited="true" range="-2.69653 -0.916298" />
                        <geom type="mesh" contype="0" conaffinity="0" group="1" mesh="calf" />
                        <geom size="0.1 0.008 0.008" pos="0 0 -0.1" quat="0.707107 0 0.707107 0" type="box" rgba="0 0 0 0" />
                        <geom name="RL_foot" size="0.02" pos="0 0 -0.2" rgba="0 0 0 0" />
                    </body>
                </body>
            </body>
        </body>

    </worldbody>
    <actuator>       
        
        <motor name="FR_hip"    gear="1"  joint="FR_hip_joint"   />
        <motor name="FR_thigh"  gear="1"  joint="FR_thigh_joint" />
        <motor name="FR_calf"   gear="1"  joint="FR_calf_joint"  />
        <motor name="FL_hip"    gear="1"  joint="FL_hip_joint"   />
        <motor name="FL_thigh"  gear="1"  joint="FL_thigh_joint" />
        <motor name="FL_calf"   gear="1"  joint="FL_calf_joint"  />
        <motor name="RR_hip"    gear="1"  joint="RR_hip_joint"   />
        <motor name="RR_thigh"  gear="1"  joint="RR_thigh_joint" />
        <motor name="RR_calf"   gear="1"  joint="RR_calf_joint"  />
        <motor name="RL_hip"    gear="1"  joint="RL_hip_joint"   />
        <motor name="RL_thigh"  gear="1"  joint="RL_thigh_joint" />
        <motor name="RL_calf"   gear="1"  joint="RL_calf_joint"  />
    </actuator>

    <sensor>
        <jointpos name="FR_hip_pos"    joint="FR_hip_joint"    noise="0.0001" />
        <jointpos name="FR_thigh_pos"  joint="FR_thigh_joint"  noise="0.0001" />
        <jointpos name="FR_calf_pos"   joint="FR_calf_joint"   noise="0.0001" />
        <jointpos name="FL_hip_pos"    joint="FL_hip_joint"    noise="0.0001" />
        <jointpos name="FL_thigh_pos"  joint="FL_thigh_joint"  noise="0.0001" />
        <jointpos name="FL_calf_pos"   joint="FL_calf_joint"   noise="0.0001" />
        <jointpos name="RR_hip_pos"    joint="RR_hip_joint"    noise="0.0001" />
        <jointpos name="RR_thigh_pos"  joint="RR_thigh_joint"  noise="0.0001" />
        <jointpos name="RR_calf_pos"   joint="RR_calf_joint"   noise="0.0001" />
        <jointpos name="RL_hip_pos"    joint="RL_hip_joint"    noise="0.0001" />
        <jointpos name="RL_thigh_pos"  joint="RL_thigh_joint"  noise="0.0001" />
        <jointpos name="RL_calf_pos"   joint="RL_calf_joint"   noise="0.0001" />

        <jointvel name="FR_hip_vel"    joint="FR_hip_joint"    noise="0.1" />
        <jointvel name="FR_thigh_vel"  joint="FR_thigh_joint"  noise="0.1" />
        <jointvel name="FR_calf_vel"   joint="FR_calf_joint"   noise="0.1" />
        <jointvel name="FL_hip_vel"    joint="FL_hip_joint"    noise="0.1" />
        <jointvel name="FL_thigh_vel"  joint="FL_thigh_joint"  noise="0.1" />
        <jointvel name="FL_calf_vel"   joint="FL_calf_joint"   noise="0.1" />
        <jointvel name="RR_hip_vel"    joint="RR_hip_joint"    noise="0.1" />
        <jointvel name="RR_thigh_vel"  joint="RR_thigh_joint"  noise="0.1" />
        <jointvel name="RR_calf_vel"   joint="RR_calf_joint"   noise="0.1" />
        <jointvel name="RL_hip_vel"    joint="RL_hip_joint"    noise="0.1" />
        <jointvel name="RL_thigh_vel"  joint="RL_thigh_joint"  noise="0.1" />
        <jointvel name="RL_calf_vel"   joint="RL_calf_joint"   noise="0.1" />

        <accelerometer name="Body_Acc" site="imu" noise="0.2"/>
        <gyro name="Body_Gyro" site="imu"/>

        <framepos name="Body_Pos" objtype=site objname="imu"/>
        <framequat name="Body_Quat" objtype=site objname="imu"/>
        
    </sensor>

</mujoco>